Workbook

Sheet Outstanding items
A1: ID | B1: System | C1: Domain | D1: Category | E1: Title | F1: Description | G1: References | H1: Options | I1: Ask / owner of answer | J1: Responsible | K1: Priority | L1: Status | M1: Raised | N1: Decision / answer | O1: Decided
A2: GEN-01 | B2: General | C2: Both | D2: Decision | E2: Supplier documentation baseline | F2: Framo, Servi/Østerbø and Normex interfaces each need one agreed signal list and functional description before FAT. | G2: Review 2026-10-21 | I2: Internal | J2: Project | K2: High | L2: Open | M2: 2026-10-21
A3: GEN-02 | B3: General | C3: Software | D3: Missing info | E3: Alarm priorities and acknowledge classes | F3: Alarm list FD-02 has no priority or acknowledgement classes; the PLC mixes auto-ack and operator ack. | G3: CAS FD Inlet OI21; FD-02 | I3: Internal | J3: Project | K3: Low | L3: Open | M3: 2026-10-21
A4: GEN-03 | B4: General | C4: Software | D4: Missing info | E4: Production HMI specification | F4: Production HMI (screens, users, access) not specified; outlet screens not built. | G4: CAS FD Oxygen OI25; CAS FD Outlet OI19 | I4: Internal | J4: Project | K4: Medium | L4: Open | M4: 2026-10-21
A5: IN-01 | B5: Inlet | C5: Both | D5: Inconsistency | E5: Framo interface baseline | F5: Three versions: Framo interface list 01.09.2025, Framo spec rev B (0000_CAS_SPEC_CTRLSYS 08.10.2025) and FD rev B. Node names differ (SpeedSetpoint vs VelocitySetpoint, AquastreamStopped vs PumpStopped); PLC writes Framo_n.SpeedSetpoint. | G5: Framo_InterfaceList_01.09.2025.docx; 0000_CAS_SPEC_CTRLSYS m kommentarer.pdf; FD §3.2.1; PRG.FramoDataProcessing | H5: Agree rev B as baseline and freeze OPC UA node names | I5: Framo | J5: Sigurd | K5: High | L5: Open | M5: 2026-10-21 | N5: Framo SCD 7664-017-1 (received 2026-10-23): logic only, no OPC UA node names or data types (addresses "TBA"). CAS signals: HMI START (M01-U04), HMI STOP (M01-U05), HMI RESET (M01-U11), REMOTE CONTROL (UY-012), SPEED SETPOINT (M01-U56), INHIBIT START (M01-Q03) from CAS; STARTING SEQU ACTIVE (UI-010), FAILED TO START (UA-011) to CAS. No pump state (UNAVAILABLE/AVAILABLE/START/REMOTE/HOLD/LOCKDOWN) as the PLC expects. See IN-34.
A6: IN-02 | B6: Inlet | C6: Both | D6: Inconsistency | E6: Heartbeat definition | F6: FD §3.2.1 text: INT counter 0..32767. FD Tabell 6 / Framo rev B: BOOL toggle + Interval/Elapsed. PLC (D1): one shared bit, PLC sets, Framo clears, timeout 10 s; HeartbeatInterval never written. Aksjonsliste #3 open. | G6: FD §3.2.1, Tabell 6; Framo spec rev B; FB.Inlet.InletControl | H6: Confirm shared-bit scheme, interval, timeout and Framo HOLD delay | I6: Framo | J6: Sigurd | K6: High | L6: Open | M6: 2026-10-21 | N6: Framo SCD 7664-017-1 (received 2026-10-23): heartbeat is a Framo standard FB #HRTB (UI-100); its fault output is ORed with HMI STOP: heartbeat loss resets the start latch and STOPS the pump. No HOLD at preset speed. Interval/timeout not given.
A7: IN-03 | B7: Inlet | C7: Both | D7: Inconsistency | E7: HOLD / LOCKDOWN recovery | F7: Framo rev B: HOLD returns to REMOTE automatically when heartbeat is back; LOCKDOWN exits on 'Sequence END'. FD Tabell 5 requires operator Reset. The PLC works either way: it follows the state the PCC reports (LIC01 frozen in HOLD, bumpless resume in REMOTE) and sends Reset only on the operator's command (since 2026-10-21 held until the state change is seen; warning FailedToReset after 2 x ResetExpectedTime). Open with Framo: which behaviour the PCC implements, edge or level on Reset, and whether the PCC panel has its own local Reset. | G7: FD Tabell 5; Framo spec rev B state diagram; FB.Inlet.InletControl; CAS FD Inlet rev A1 OI2/OI3 | H7: Reset required (FD) vs automatic (Framo) | I7: Framo | J7: Sigurd | K7: High | L7: Open | M7: 2026-10-21 | N7: Framo SCD 7664-017-1 (received 2026-10-23): no HOLD or LOCKDOWN state in the SCD. Heartbeat loss = stop; drive trip / FSL trip -> pump block YF, cleared by HMI RESET (also resets the drive). Ask Framo whether HOLD (rev B spec) still exists.
A8: IN-04 | B8: Inlet | C8: Software | D8: Code bug | E8: Stop accepted only in REMOTE | F8: Framo rev B accepts Stop only in REMOTE; PLC stop timer also arms in STARTING/HOLD and raises 'Stopp feilet'. Heartbeat loss in START/AVAILABLE undefined by Framo. | G8: Framo spec rev B; FB.Inlet.InletControl ShutdownTransitionTimer | I8: Framo | J8: Sigurd | K8: Medium | L8: Open | M8: 2026-10-21
A9: IN-05 | B9: Inlet | C9: Software | D9: Decision | E9: LIC01 response to pump trip / rejoin | F9: Sim test 2026-10-21: losing 1 of 3 pumps dips level 3.4 cm; rejoin overshoots 2.7 cm (no feed-forward on running pumps, integral windup at 130 rpm). | G9: Sim test 2026-10-21 (CasRioSim 2.4.5) | H9: Feed-forward N/(N-1); anti-windup; gain scheduling per FD Tabell 8 | I9: Internal | J9: Sigurd | K9: High | L9: In progress | M9: 2026-10-21 | N9: Baseline sim 2026-10-22: pump 3 out -> level 6.0 -> 3.0 cm, 4 min back; pump 3 restart -> 9.1 cm, mostly during its START (own preset speed while the others still ran fast). Implemented in CODESYS 2026-10-22 (not yet downloaded/tested): LIC01 output = TOTAL speed of the pumps in level control; pumps in REMOTE share (total - actual speed of the pumps starting/stopping) / N, limited 40-130 rpm, in PenInletSupervisor.AutoSpeedSetpoint. A trip or a start is compensated in the same cycle; Kp 450 -> 1350 (total). Retained Kp must be set to 1350 after download. HMI: heimdall-cas-hmi PR #6. Sim test pending (PLC busy). | Live test 2026-10-22 (PFC200 10.1.2.41, main 1a427c0, CAS plant 10.1.2.150, after Reset Origin): Pen Start from drained (-3.4 cm): pumps tracked to 260 rpm total, REMOTE at 85.5 rpm share (bumpless), level 6.6 cm peak (0.6 cm overshoot), settled 6.1 cm in ~2.5 min with 3 x 74 rpm. Pump stopped by the pump count: the other two took its share in the same cycle, level dip 6.0 -> 5.2 cm, back to 6.3 cm. Pump trip test still to do.
A10: IN-06 | B10: Inlet | C10: Both | D10: Decision | E10: Minimum controllable overheight | F10: O-60 and S-75 use 0.5 cm overheight. Level transmitter resolution ~1 mm, plus surface waves. | G10: FD Tabell 10; design basis Table 16 | H10: Set minimum setpoint and low-level alarm limits | I10: Internal | J10: Project | K10: High | L10: Open | M10: 2026-10-21
A11: IN-07 | B11: Inlet | C11: Software | D11: Inconsistency | E11: LIC01 parameter sets | F11: FD wants 3 parameter sets by number of pumps (P 0.5/1/2, Ti 600 s). PLC has one (Kp 450, Ti 60 s tested in sim). | G11: FD Tabell 8; ConfigValues PenConfig; D6 | H11: Update FD to tested values or implement scheduling | I11: Internal | J11: Sigurd | K11: Medium | L11: In progress | M11: 2026-10-21 | N11: With the shared total output (IN-05) the loop gain no longer depends on the number of pumps: one parameter set (Kp 1350 total rpm/m, Ti 60 s) replaces FD Tabell 8's three. Update FD to rev C after the sim test. | Live test 2026-10-22 (PFC200 10.1.2.41, main 1a427c0, CAS plant 10.1.2.150, after Reset Origin): one parameter set Kp 1350 / Ti 60 s works for 3 and 2 pumps (start-up and pump stop above).
A12: IN-08 | B12: Inlet | C12: Physical | D12: Inconsistency | E12: Flow per operating mode | F12: FD Tabell 10 O-35 = 34 000 m3/h; design basis: max requirement 27 000 m3/h, 20 000 m3/h per pump. Framo action WS-Aug #20 '26 000 ok for emergency mode?' open. | G12: FD Tabell 10; design basis §4.4; Framo aksjonsliste | I12: Internal / Framo | J12: Project | K12: Medium | L12: Open | M12: 2026-10-21
A13: IN-09 | B13: Inlet | C13: Software | D13: PLC gap | E13: Pen level alarms missing | F13: FD Tabell 7 and alarm list rows 29-32: control deviation, low level, high level, fault per level sensor. PenAlarmDUT has only LevelMeasurementLost. | G13: FD Tabell 7; FD-02 alarm list | I13: Internal | J13: Sigurd | K13: Medium | L13: In progress | M13: 2026-10-21 | N13: Control deviation implemented in CODESYS 2026-10-22 (not yet downloaded/tested): Pen.Alarm.LevelDeviationHigh / LevelDeviationLow when LIC01 is in auto and the over-height is more than PenConfig.LevelDeviationLimit (0.02 m) above / below the setpoint for LevelDeviationDelay (5 min); not during start-up, manual, SafeOutput or HOLD freeze. Fault per level sensor already covered by the transmitters' Quality alarms. Still open: absolute low / high level alarms (alarm list rows 31-32). HMI: heimdall-cas-hmi PR #8. | Live test 2026-10-22 (PFC200 10.1.2.41, main 1a427c0, CAS plant 10.1.2.150, after Reset Origin): not tested yet.
A14: IN-10 | B14: Inlet | C14: Software | D14: PLC gap | E14: Pump speed deviation alarm | F14: Not implemented (D7). Alarm list has 'Hastighetsavvik innløpspumpe 1' twice (rows 24/25). | G14: FD-02 alarm list; program design D7 | I14: Internal | J14: Sigurd | K14: Medium | L14: In progress | M14: 2026-10-21 | N14: Implemented in CODESYS 2026-10-22 (not yet downloaded/tested): Inlet[i].InletPump.Alarm.SpeedDeviation (operator ack) when the pump is in REMOTE and |VelocitySetpoint - MotorVelocity| > InletConfig[i].SpeedDeviationLimit (10 rpm) for SpeedDeviationDelay (30 s); limit 0 = off. Retained in InletConfigDUT (Reset Origin with IN-15). Duplicate alarm-list row removed in FD-01 rev C. | Live test 2026-10-22 (PFC200 10.1.2.41, main 1a427c0, CAS plant 10.1.2.150, after Reset Origin): not tested yet.
A15: IN-11 | B15: Inlet | C15: Software | D15: Code bug | E15: LowPower/HighPower in common alarm | F15: PLC PumpCommonError includes LowPower/HighPower; FD and alarm list say notification only, not in common alarm. | G15: FB.Inlet.InletControl.AlarmHandling; FD-02 | H15: Remove from PumpCommonError | I15: Internal | J15: Sigurd | K15: Low | L15: In progress | M15: 2026-10-21 | N15: Implemented in CODESYS 2026-10-22 (not yet downloaded): LowPower / HighPower removed from PumpCommonError; their own alarms are notifications (AutoAcknowledge), as FD Tabell 7. | Live test 2026-10-22 (PFC200 10.1.2.41, main 1a427c0, CAS plant 10.1.2.150, after Reset Origin): not tested yet.
A16: IN-12 | B16: Inlet | C16: Both | D16: Missing info | E16: Vacuum / air evacuation system | F16: Not in either Framo document. PLC reads PressureCompressedAir, LSL01/LSH02, StatusV001/V002; FD uses LSL31/LSH32/XV31/XV32; VacuumSystemAlarmDUT empty; Framo cabinet drawing lacks the evacuation unit (Aksjonsliste #19). | G16: FD Tabell 6; FD-02 'Overfylling i Luftevakuering'; Framo aksjonsliste #19 | I16: Framo | J16: Sigurd | K16: Medium | L16: Open | M16: 2026-10-21 | N16: Framo SCD 7664-017-1 (received 2026-10-23): air evacuation: start latch AND no stop AND release valve UY-004A closed opens comp. air valve UY-003A (ejector) until LSH-002A; pump start only when LSL-001A is wet; NOT LSL or sensor deviation (LSH AND NOT LSL, UA-001A) trips the pump (FSL). HMI STOP opens the release valve. | Framo P&ID 7664-021-1 (08.09.26, received 2026-10-23): per inlet one vacuum chamber with ejector: compressed-air valve UY-003x (ZSO/ZSC-003x), release valve UY-004x (ZSO/ZSC-004x), LSH-002x, LSL-001x; all their signals go to the Framo UCP only (none to the client system). No compressed-air pressure transmitter, although the PLC reads Framo_n.PressureCompressedAir; the PLC has one status bit per valve (StatusV001/V002), the P&ID two limit switches per valve. Compressed air supply comes from client scope (one line to all three units). Drafting error: the release valve of unit A is tagged UY-004B (B, C correct).
A17: IN-13 | B17: Inlet | C17: Both | D17: Missing info | E17: Framo autonomous behaviour | F17: Need: HOLD preset speed, start-up ramp speed (LIC01 tracks it), whether Available excludes DriveNotInRemote/PumpStopped, engineering units of VelocitySetpoint/MotorVelocity (FD assumes 40-130 rpm). | G17: FD §3.2.1-3.2.2 | I17: Framo | J17: Sigurd | K17: High | L17: Open | M17: 2026-10-21 | N17: Framo SCD 7664-017-1 (received 2026-10-23): start: drive runs at a fixed 40 rpm start setpoint ("adjust while commissioning"); READY TO REMOTE CNTRL (UI-013) 30 s after DRIVE RUNNING; speed from CAS only when CAS gives REMOTE CONTROL (UY-012) and ready to remote. FAILED TO START (UA-011) when the start sequence stays active for "time" (not given).
A18: IN-14 | B18: Inlet | C18: Both | D18: Decision | E18: Emergency stop chain | F18: Framo E-stops are in series and stop all lines (Aksjonsliste #16). Confirm intended; oxygen stop on E-stop must go through Heimdall PLC. | G18: Aksjonsliste #16 | I18: Internal / Framo | J18: Project | K18: Medium | L18: Open | M18: 2026-10-21
A19: IN-15 | B19: Inlet | C19: Both | D19: Decision | E19: Functions on HOLD in FD | F19: Automatic pump start/stop on LIC output, pump rotation (#18), manual level setpoint, auto outlet close on pump stop, E-stop alarm. | G19: FD rev B HOLD marks | I19: Internal | J19: Project | K19: Medium | L19: In progress | M19: 2026-10-21 | N19: Automatic pump start/stop and rotation implemented in CODESYS 2026-10-22 (not yet downloaded/tested), InletSupervisor.PumpCount: candidates = InletConfig[i].InletPump.Enable AND auto AND not UNAVAILABLE/LOCKDOWN. Pen Start starts all candidates; with LIC01 in auto and no pump changing: stop the pump with most running days when the others would run <= PumpTargetSpeed (85 rpm) for PumpRemoveDelay (15 min); start the standby with fewest running days when the share >= PumpAddSpeed (115 rpm) for PumpAddDelay (2 min); rotation after PumpCycleTime (24 h) in REMOTE, make-before-break. Settings retained in PenConfig (Reset Origin on next download). Still open from the HOLD list: manual level setpoint, auto outlet close on pump stop, E-stop alarm. | Live test 2026-10-22 (PFC200 10.1.2.41, main 1a427c0, CAS plant 10.1.2.150, after Reset Origin): pump count: with PumpTargetSpeed 115 / delay 60 s (test values) the pump with most running days stopped, 2 pumps at ~112 rpm, no flapping (PumpAddSpeed 125). Rotation (PumpCycleTime 2 min, test value): standby started first, old pump stopped once the new one was in REMOTE, level 5.1-7.1 cm during the handover (IN-31). All defaults restored afterwards (85 / 115 rpm, 15 / 2 min, 24 h).
A20: IN-16 | B20: Inlet | C20: Both | D20: Inconsistency | E20: Tag numbering | F20: FD motor table nn-PM01..03 / PU01..03 vs inlet and oxygen sections PM31..33 / PU41..43. Align with P&ID rev A. | G20: FD rev B; CAS PID and loop diagrams rev A | I20: Internal | J20: Sigurd | K20: Low | L20: Open | M20: 2026-10-21 | N20: Framo P&ID 7664-021-1 (08.09.26, received 2026-10-23): Framo tags: pumps P-01A/B/C, level switches LSL-001A..C / LSH-002A..C, valves UY-003A..C / UY-004A..C (SCD uses the A tags). FD uses PM31..33 / PU41..43, LSL31 / LSH32, XV31 / XV32; PLC uses LSL01 / LSH02, V001 / V002.
A21: IN-17 | B21: Inlet | C21: Software | D21: Code bug | E21: Old OPC UA node name SpeedSetpoint | F21: PRG.FramoDataProcessing writes Framo_n.SpeedSetpoint; Framo rev B names it VelocitySetpoint. | G21: PRG.FramoDataProcessing | I21: Internal | J21: Sigurd | K21: Medium | L21: Open | M21: 2026-10-21
A22: IN-18 | B22: Inlet | C22: Software | D22: Code bug | E22: LIC01 integral windup at speed limit | F22: Integral keeps building while output is clamped at 130 rpm (seen in sim 2026-10-21 after a pump trip); causes overshoot when the pump returns. | G22: Sim test 2026-10-21; FB.Inlet.InletSupervisor LIC01 | H22: Anti-windup / conditional integration | I22: Internal | J22: Sigurd | K22: Medium | L22: Closed | M22: 2026-10-21 | N22: Not a bug. Util.PID adapts the integral while the output is limited (anti-windup). Sim test 2026-10-22: one of three pumps out, LIC01 output rose 74 -> 107 rpm and never reached 130 (LimitsActive FALSE). The dip/overshoot is the missing compensation of the pump count, see IN-05. | O22: 2026-10-22
A23: IN-19 | B23: Inlet | C23: Software | D23: Code bug | E23: RIO link loss freezes level | F23: When an InletRIO link is lost the last level values are kept and the pair is not invalidated, so LIC01 controls on a frozen level. | G23: CAS FD Inlet OI17; FB.Inlet.InletSensors | H23: Invalidate pair on RIO comm loss | I23: Internal | J23: Sigurd | K23: High | L23: Fixed | M23: 2026-10-21 | N23: Fixed in CODESYS 2026-10-22: InletControl / InletSensors get RIOCommOK = GVLIO.InletRIO[i].Status.CommOK; without it both transmitters of that inlet count as BadQuality, so only that pair drops out of LIC01's PV (all three lost -> LevelMeasurementLost, SafeOutput). Sim test 2026-10-22 (PFC200 vs CAS plant 10.1.2.150): pair 1 out for 60 s with 3 pumps in REMOTE, PV continued on pairs 2-3, LIC01 output 74.1-74.3 rpm, pair back without a jump. Realistic link-down test (5 s socket timeout) with the simulator fault of heimdall-cas-simulation PR #17. | O23: 2026-10-22
A24: IN-20 | B24: Inlet | C24: Software | D24: PLC gap | E24: Interlocks I2 and I3 missing | F24: I2: 2oo3 LS7nmHH stops the pump; I3: group start only with the outlet open. Neither is in the PLC. | G24: CAS FD Inlet OI20; FD rev B | I24: Internal | J24: Sigurd | K24: High | L24: Open | M24: 2026-10-21
A25: IN-21 | B25: Inlet | C25: Software | D25: Code bug | E25: Task watchdogs disabled | F25: Main task 20 ms, OPC_Processing and Datasources 50 ms; watchdogs off in PFC200_Sim. | G25: CAS FD Inlet OI23; task configuration | H25: Enable with margin | I25: Internal | J25: Sigurd | K25: Medium | L25: Open | M25: 2026-10-21 | N25: 2026-10-23 measured on the PFC200 (10.1.2.41): htop CPU 86 %, load average 2.6 (single core); task monitor: Task 20 ms avg 3.0 / max 5.0 ms (about 15 %), OPC_Processing 50 ms avg 0.11 / max 0.68 ms, DatasourcesTask 50 ms avg 3.4 / max 154 ms, jitter up to 104 ms. IEC tasks about 22 %: the rest is runtime threads (OPC UA server for the HMI / 7 sessions, OPC UA client of the data sources). Next: thread names, HMI-off test, data source update rate; then a task split (20 ms outlet + CommonRIO, 100 ms control incl. FramoDataProcessing, data sources lowest) and watchdogs per task. Task config kept as is for now.
A26: IN-22 | B26: Inlet | C26: Software | D26: PLC gap | E26: Level setpoint not from operating mode | F26: FD: setpoint follows the operating mode (O-35/O-45/O-60/S-75). PLC uses an operator setpoint only. | G26: CAS FD Inlet OI14 | I26: Internal | J26: Sigurd | K26: Medium | L26: Open | M26: 2026-10-21
A27: IN-23 | B27: Inlet | C27: Software | D27: PLC gap | E27: Restart after power failure | F27: FD 'Motor-Forrigling' + motor table T3/T4: motors that were running restart after a power cut, larger ones in sequence (1 hydraulic pump, 2a/2b/2c inlet pumps, 3 oxygenator pumps; vacuum J01A-C auto-restart). PLC: PenStart is not retained, so after a PLC power loss nothing restarts; if only the Framo cabinets lose power, all pumps restart together once Available. Needs a retained 'was running' state per motor and the restart sequence with delays. | G27: FD rev B 'Motor-Forrigling', Tabell T3/T4; CAS FD Inlet OI16; FB.Inlet.InletSupervisor (PenStart) | I27: Internal | J27: Sigurd | K27: Medium | L27: Open | M27: 2026-10-21
A28: IN-24 | B28: Inlet | C28: Physical | D28: Missing info | E28: Level transmitter signal direction and model | F28: 4 mA = low or high? VEGAPULS C21 vs C22; outside full scale assumed 2 m. | G28: CAS FD Inlet OI18; Sensors folder | I28: Internal | J28: Sigurd | K28: Medium | L28: Open | M28: 2026-10-21
A29: IN-25 | B29: Inlet | C29: Both | D29: Missing info | E29: IP plan and network drawing | F29: No IP plan or network drawing for PLC, RIOs, Framo controllers, drives and HMI. | G29: CAS FD Inlet OI23 | I29: Internal | J29: Project | K29: Medium | L29: Open | M29: 2026-10-21
A30: IN-26 | B30: Inlet | C30: Physical | D30: Inconsistency | E30: Framo hardware designations | F30: Framo spec rev B CX8190 vs drawing 874.001 CX8200; SX1000 vs SR2000 pump. | G30: CAS FD Inlet OI19; 15169-874.001 | I30: Framo | J30: Sigurd | K30: Low | L30: Open | M30: 2026-10-21
A31: IN-27 | B31: Inlet | C31: Software | D31: Decision | E31: Restart after a pump trip | F31: Should a tripped inlet pump restart by itself? | G31: FD rev B §3.2.1, Tabell 6 (LOCKDOWN), 'Motor-Forrigling' | I31: Internal | J31: Project | K31: Low | L31: Decided | M31: 2026-10-21 | N31: Given by FD rev B: a fault gives LOCKDOWN; the operator sends Reset after fixing it; the pump then restarts while group start (Pen Start) is active. PLC complies (start request stays latched; seen in sim 2026-10-21). | O31: 2026-10-21
A32: IN-28 | B32: Inlet | C32: Both | D32: Decision | E32: Emergency stop as interlock with auto-restart | F32: FD motor table lists emergency stop as the interlock for PM01-03, PU01-03 and XV01-M01, and 'Motor-Forrigling' says a motor stopped by an interlock in auto restarts automatically when the interlock clears (group start still active). Read literally, pumps restart when the E-stop is released — normally an E-stop reset requires a deliberate restart. Framo E-stops are in series across all lines. | G32: FD rev B 'Motor-Forrigling', Tabell T3; Aksjonsliste #16 | H32: E-stop release requires operator restart (recommended) / auto-restart as FD | I32: Internal / Framo | J32: Project | K32: High | L32: Open | M32: 2026-10-21
A33: IN-29 | B33: Inlet | C33: Software | D33: PLC gap | E33: Reset to Framo held until state change | F33: HMI Reset was passed straight through as a level and never cleared by the PLC; a 1 s HMI pulse could be lost in the OPC UA data source. | G33: FB.Inlet.InletControl; InletConfigDUT.ResetExpectedTime; InletPumpAlarmDUT.FailedToReset | I33: Internal | J33: Sigurd | K33: Medium | L33: Fixed | M33: 2026-10-21 | N33: Fixed in CODESYS 2026-10-21 (FB.Inlet.InletControl): Command.Reset accepted in HOLD/LOCKDOWN, latched as ResetRequest and cleared when the state change is seen; no change within 2 x InletConfig.ResetExpectedTime (default 5 s) -> Reset withdrawn and warning Alarm.FailedToReset (AutoAcknowledge). Command.Reset is exported read/write over OPC UA (checked on 10.1.2.41). Pre-compile clean; full compile and sim test pending. | O33: 2026-10-21
A34: IN-30 | B34: Inlet | C34: Software | D34: PLC gap | E34: Reset button on the HMI | F34: No way for the operator to give Reset to the Framo controller (FD 3.2.1: Reset from the HMI). | G34: heimdall-cas-hmi PR #5 (task/inlet-pump-reset-button); CAS FD Inlet OI24 | I34: Internal | J34: Sigurd | K34: Medium | L34: In progress | M34: 2026-10-21 | N34: Test HMI: Reset button per inlet pump, enabled in HOLD/LOCKDOWN, with confirmation (PR #5, open). Production HMI needs the same.
A35: OX-01 | B35: Oxygen | C35: Physical | D35: Decision | E35: Oxygen supplier | F35: Supplier for oxygen chosen. | G35: Project meeting 2026-10-21 | I35: Internal | J35: Project | K35: High | L35: Decided | M35: 2026-10-21 | N35: Normex | O35: 2026-10-21
A36: OX-02 | B36: Oxygen | C36: Physical | D36: Missing info | E36: Oxygen supply and safety interface (Normex) | F36: Supply type (LOX / generator / valve panel), normal and minimum supply pressure, low-supply-pressure signal, PLC-controlled master shut-off valve, non-return protection (HAZID: water back into oxygenator and O2 tank). Supply pressure is display-only in the PLC. | G36: HAZID oksygen; PenControl O2InjectionPressureSensor | I36: Normex | J36: Sigurd | K36: High | L36: Open | M36: 2026-10-21
A37: OX-03 | B37: Oxygen | C37: Both | D37: Inconsistency | E37: O2 control valve type | F37: FD: PWM solenoid valve 'via 4-20 mA'. PLC: proportional valve 4-20 mA, 4 mA = closed, 2 s ramp. Linde photos show 'pwm_ventil'; Normex sketch (15.10.26) shows a motorised valve. Signal, stroke time, fail position, position feedback unknown. | G37: FD §3.2.4; FB.OxySystem.OxyControl | I37: Normex | J37: Sigurd | K37: High | L37: Open | M37: 2026-10-21
A38: OX-04 | B38: Oxygen | C38: Both | D38: Missing info | E38: O2 flow meter | F38: Unit (kg/h or Nl/min), range and signal type. PLC and FIC work in kg/h; FD FIC in l/min. | G38: FD Tabell 14; ConfigValues | I38: Normex | J38: Sigurd | K38: Medium | L38: Open | M38: 2026-10-21
A39: OX-05 | B39: Oxygen | C39: Physical | D39: Missing info | E39: Injector model and gas ratio | F39: FlowMax 104.2 kg/h = Chucaotech at 15 % v/v; same model 34.7 kg/h at 5 %. Confirm model, allowed ratio, valve and flow meter range. | G39: Oppsett innløsere CT.xlsx; ConfigValues OxySystemConfig | I39: Normex / Chucaotech | J39: Sigurd | K39: Medium | L39: Open | M39: 2026-10-21
A40: OX-06 | B40: Oxygen | C40: Software | D40: PLC gap | E40: High-high O2 / supersaturation shut-off | F40: FD (HOLD) asks oxygenation to close on high-high O2 near the inlet. No HH or TDGP shut-off in OxyControl/InletSupervisor. | G40: FD §3.2.4 | H40: Decide limits, sensors, latching | I40: Internal | J40: Sigurd | K40: High | L40: Open | M40: 2026-10-21
...

Sheet Summary
A1: Open items by system and priority (counts update from the register)
A3: System | B3: High | C3: Medium | D3: Low | E3: Open total | F3: Decided | G3: Fixed | H3: All items
A4: General | B4: =COUNTIFS('Outstanding items'!$B:$B,$A4,'Outstanding items'!$K:$K,"High",'Outstanding items'!$L:$L,"Open") | C4: =COUNTIFS('Outstanding items'!$B:$B,$A4,'Outstanding items'!$K:$K,"Medium",'Outstanding items'!$L:$L,"Open") | D4: =COUNTIFS('Outstanding items'!$B:$B,$A4,'Outstanding items'!$K:$K,"Low",'Outstanding items'!$L:$L,"Open") | E4: =COUNTIFS('Outstanding items'!$B:$B,$A4,'Outstanding items'!$L:$L,"Open") | F4: =COUNTIFS('Outstanding items'!$B:$B,$A4,'Outstanding items'!$L:$L,"Decided") | G4: =COUNTIFS('Outstanding items'!$B:$B,$A4,'Outstanding items'!$L:$L,"Fixed") | H4: =COUNTIFS('Outstanding items'!$B:$B,$A4)
A5: Inlet | B5: =COUNTIFS('Outstanding items'!$B:$B,$A5,'Outstanding items'!$K:$K,"High",'Outstanding items'!$L:$L,"Open") | C5: =COUNTIFS('Outstanding items'!$B:$B,$A5,'Outstanding items'!$K:$K,"Medium",'Outstanding items'!$L:$L,"Open") | D5: =COUNTIFS('Outstanding items'!$B:$B,$A5,'Outstanding items'!$K:$K,"Low",'Outstanding items'!$L:$L,"Open") | E5: =COUNTIFS('Outstanding items'!$B:$B,$A5,'Outstanding items'!$L:$L,"Open") | F5: =COUNTIFS('Outstanding items'!$B:$B,$A5,'Outstanding items'!$L:$L,"Decided") | G5: =COUNTIFS('Outstanding items'!$B:$B,$A5,'Outstanding items'!$L:$L,"Fixed") | H5: =COUNTIFS('Outstanding items'!$B:$B,$A5)
A6: Oxygen | B6: =COUNTIFS('Outstanding items'!$B:$B,$A6,'Outstanding items'!$K:$K,"High",'Outstanding items'!$L:$L,"Open") | C6: =COUNTIFS('Outstanding items'!$B:$B,$A6,'Outstanding items'!$K:$K,"Medium",'Outstanding items'!$L:$L,"Open") | D6: =COUNTIFS('Outstanding items'!$B:$B,$A6,'Outstanding items'!$K:$K,"Low",'Outstanding items'!$L:$L,"Open") | E6: =COUNTIFS('Outstanding items'!$B:$B,$A6,'Outstanding items'!$L:$L,"Open") | F6: =COUNTIFS('Outstanding items'!$B:$B,$A6,'Outstanding items'!$L:$L,"Decided") | G6: =COUNTIFS('Outstanding items'!$B:$B,$A6,'Outstanding items'!$L:$L,"Fixed") | H6: =COUNTIFS('Outstanding items'!$B:$B,$A6)
A7: Outlet | B7: =COUNTIFS('Outstanding items'!$B:$B,$A7,'Outstanding items'!$K:$K,"High",'Outstanding items'!$L:$L,"Open") | C7: =COUNTIFS('Outstanding items'!$B:$B,$A7,'Outstanding items'!$K:$K,"Medium",'Outstanding items'!$L:$L,"Open") | D7: =COUNTIFS('Outstanding items'!$B:$B,$A7,'Outstanding items'!$K:$K,"Low",'Outstanding items'!$L:$L,"Open") | E7: =COUNTIFS('Outstanding items'!$B:$B,$A7,'Outstanding items'!$L:$L,"Open") | F7: =COUNTIFS('Outstanding items'!$B:$B,$A7,'Outstanding items'!$L:$L,"Decided") | G7: =COUNTIFS('Outstanding items'!$B:$B,$A7,'Outstanding items'!$L:$L,"Fixed") | H7: =COUNTIFS('Outstanding items'!$B:$B,$A7)
A8: Total | B8: =SUM(B4:B7) | C8: =SUM(C4:C7) | D8: =SUM(D4:D7) | E8: =SUM(E4:E7) | F8: =SUM(F4:F7) | G8: =SUM(G4:G7) | H8: =SUM(H4:H7)

Sheet Legend
A1: How to use
A2: Add a row | B2: One row per item. ID = system prefix (GEN/IN/OX/OUT) + next number. Never reuse an ID.
A3: Domain | B3: Physical = equipment, wiring, instruments, supplier hardware; Software = PLC/HMI/simulator code and configuration; Both = needs a physical and a software change.
A4: Category | B4: Decision = someone must choose; Inconsistency = documents/PLC disagree; Missing info = data needed from a supplier or the project; Missing hardware = sensor/actuator/signal not on drawings or not ordered; Code bug = PLC/HMI does something wrong; PLC gap = FD/alarm list requires something the PLC does not do yet.
A5: Ask / owner of answer | B5: Who must answer: Framo, Servi, Østerbø, Normex, Chucaotech, Customer, Internal, Project.
A6: Responsible | B6: Who follows up internally.
A7: Status | B7: Open → In progress → Decided (fill Decision/answer and Decided date) → Fixed (changed in CODESYS / code: whole row green, Decision/answer says what was done and how it was tested) → Closed (verified, docs updated).
A8: Priority | B8: High = blocks FAT, safety or supplier delivery; Medium = needed before commissioning; Low = clean-up.
A9: Sources | B9: Initial content: document/PLC review 2026-10-21 (FD-01 rev B, FD-02 alarm list rev A, Framo spec rev B, Servi drawings A1 and JB 18068, P&ID rev A, PLC heimdall-plc main) and project meeting 2026-10-21.
